Workbook

Sheet Ex.excel01
A1: Tabela de Produtos da Cafeteria
A2: id_Produto | B2: Tipo_de_Cafe | C2: Tamanho | D2: Valor_unitário | E2: Quantidade
A3: 1 | B3: Ara | C3: G | D3: 3 | E3: 10
A4: 2 | B4: Ara | C4: G | D4: 29 | E4: 20
A5: 3 | B5: Lib | C5: M | D5: 3 | E5: 30
A6: 4 | B6: Robusto | C6: P | D6: 13 | E6: 40

Sheet Ex.excel02
A1: Falidos e Quebrados LTDA.
A2: Funcionário | B2: Produtos | C2: Vendas | D2: Resultado
A3: Abrilina | B3: Mouse | C3: 8 | D3: =IF(Ex.excel02!$C$3:$C$8 > 5, "Ótimo",(IF(Ex.excel02!$C$3:$C$8< 5, "Péssimo", "Regular"))) -> Ótimo
A4: Cheropita | B4: Teclado | C4: 5 | D4: =IF(Ex.excel02!$C$3:$C$8 > 5, "Ótimo",(IF(Ex.excel02!$C$3:$C$8< 5, "Péssimo", "Regular"))) -> Regular
A5: Aldegunda | B5: Monitor | C5: 9 | D5: =IF(Ex.excel02!$C$3:$C$8 > 5, "Ótimo",(IF(Ex.excel02!$C$3:$C$8< 5, "Péssimo", "Regular"))) -> Ótimo
A6: Arquibaldo | B6: Gabinete | C6: 4 | D6: =IF(Ex.excel02!$C$3:$C$8 > 5, "Ótimo",(IF(Ex.excel02!$C$3:$C$8< 5, "Péssimo", "Regular"))) -> Péssimo
A7: Clarisbadeu | B7: Disquete | C7: 6 | D7: =IF(Ex.excel02!$C$3:$C$8 > 5, "Ótimo",(IF(Ex.excel02!$C$3:$C$8< 5, "Péssimo", "Regular"))) -> Ótimo
A8: Fredolino | B8: Impressora | C8: 3 | D8: =IF(Ex.excel02!$C$3:$C$8 > 5, "Ótimo",(IF(Ex.excel02!$C$3:$C$8< 5, "Péssimo", "Regular"))) -> Péssimo

Sheet Ex.excel03
A1: Notas Escolares
A2: RA | B2: Nome de aluno | C2: Nota 1 Trimestre | D2: Nota 2 Trimestre | E2: Nota 3 Trimeste | F2: Média Final | G2: Resultado
A3: 2001 | B3: Astro | C3: 5 | D3: 6 | E3: 8 | F3: =AVERAGE(C3:E3) -> 6.3333333 | G3: =IF(Ex.excel03!$F$3:$F$7>= 6, "Aprovado", "Reprovado") -> Aprovado
A4: 2002 | B4: Celeste | C4: 10 | D4: 7 | E4: 8 | F4: =AVERAGE(C4:E4) -> 8.3333333 | G4: =IF(Ex.excel03!$F$3:$F$7>= 6, "Aprovado", "Reprovado") -> Aprovado
A5: 2003 | B5: Elvira | C5: 5 | D5: 2 | E5: 8 | F5: =AVERAGE(C5:E5) -> 5 | G5: =IF(Ex.excel03!$F$3:$F$7>= 6, "Aprovado", "Reprovado") -> Reprovado
A6: 2004 | B6: Homer | C6: 2 | D6: 1 | E6: 3 | F6: =AVERAGE(C6:E6) -> 2 | G6: =IF(Ex.excel03!$F$3:$F$7>= 6, "Aprovado", "Reprovado") -> Reprovado
A7: 2005 | B7: Chevrolet da Silva | C7: 4 | D7: 7 | E7: 8 | F7: =AVERAGE(C7:E7) -> 6.3333333 | G7: =IF(Ex.excel03!$F$3:$F$7>= 6, "Aprovado", "Reprovado") -> Aprovado

Sheet Ex.excel04
A1: Recrutamento para vaga do emprego
A2: Nome | B2: Idade | C2: Ensino médio | D2: Curso Técnico | E2: Anos de experiência na área | F2: Situação
A3: Alfa Romeu Julia | B3: 17 | C3: Não | D3: Sim | E3: 1 | F3: =IF(AND(Ex.excel04!$B$3:$B$7>=18,Ex.excel04!$C$3:$C$7, Ex.excel04!$D$3:$D$7 = "Sim", Ex.excel04!$E$3:$E$7 >=3), "Apto", "Não Apto") -> Não Apto
A4: Fusclaudia de Oliveira | B4: 24 | C4: Sim | D4: Sim | E4: 3 | F4: =IF(AND(Ex.excel04!$B$3:$B$7>=18,Ex.excel04!$C$3:$C$7, Ex.excel04!$D$3:$D$7 = "Sim", Ex.excel04!$E$3:$E$7 >=3), "Apto", "Não Apto") -> Apto
A5: Unotavio dos Santos | B5: 28 | C5: Sim | D5: Sim | E5: 4 | F5: =IF(AND(Ex.excel04!$B$3:$B$7>=18,Ex.excel04!$C$3:$C$7, Ex.excel04!$D$3:$D$7 = "Sim", Ex.excel04!$E$3:$E$7 >=3), "Apto", "Não Apto") -> Apto
A6: Nissan Silvia | B6: 18 | C6: Sim | D6: Não | E6: 1 | F6: =IF(AND(Ex.excel04!$B$3:$B$7>=18,Ex.excel04!$C$3:$C$7, Ex.excel04!$D$3:$D$7 = "Sim", Ex.excel04!$E$3:$E$7 >=3), "Apto", "Não Apto") -> Não Apto
A7: Ferrari Enzo | B7: 22 | C7: Sim | D7: Sim | E7: 2 | F7: =IF(AND(Ex.excel04!$B$3:$B$7>=18,Ex.excel04!$C$3:$C$7, Ex.excel04!$D$3:$D$7 = "Sim", Ex.excel04!$E$3:$E$7 >=3), "Apto", "Não Apto") -> Não Apto

Sheet Panilha_tratada
A1: status | B1: nome | C1: cpf | D1: idade | E1: data_nascimento | F1: cidade | G1: regiao | H1: renda_mensal | I1: credito_tomado | J1: flag_inadimplente | K1: qtde_batalhas | L1: nivel_risco | M1: análise_risco | N1: análise_risco2 | O1: valor_solicitado | P1: liberação_de_crédito
A2: Ativo | B2: Ellaria Baelish | C2: 000.000.336-00 | D2: 32 | E2: 34347 | F2: Ninho da Águia | G2: Vale | H2: 15600 | I2: 0 | J2: Sim | K2: 34 | L2: =IFS(K2<=10,"Baixo",K2<=25, "Médio", K2>25, "Alto") -> Alto | M2: =IF(AND(J2="Sim", L2="Alto"),"Negado","Aceito") -> Negado | N2: =IF(AND(I2> 50000, J2 = "Sim"),"Negativa", "Positiva") -> Positiva | O2: 16000 | P2: =IF(AND(Q2=1,A2="Ativo"), O2*1.08, 0) -> 17280 | Q2: =IF(AND(M2="Negado", N2="Negativa"),0,1) -> 1
A3: Inativo | B3: Stannis Lannister | C3: 36100 | D3: 24 | E3: 37313 | F3: Ponta Tempestade | G3: Terras Da Tempestade | H3: 11000 | I3: 76500 | J3: Sim | K3: 33 | L3: =IFS(K3<=10,"Baixo",K3<=25, "Médio", K3>25, "Alto") -> Alto | M3: =IF(AND(J3="Sim", L3="Alto"),"Negado","Aceito") -> Negado | N3: =IF(AND(I3> 50000, J3 = "Sim"),"Negativa", "Positiva") -> Negativa | O3: 26000 | P3: =IF(AND(Q3=1,A3="Ativo"), O3*1.08, 0) -> 0 | Q3: =IF(AND(M3="Negado", N3="Negativa"),0,1) -> 0
A4: Ativo | B4: Asha Hornwood | C4: 000.000.363-00 | D4: 33 | E4: 34144 | F4: Pedra do Dragão | G4: Terras Da Coroa | H4: 21500 | I4: - | J4: Não | K4: 22 | L4: =IFS(K4<=10,"Baixo",K4<=25, "Médio", K4>25, "Alto") -> Médio | M4: =IF(AND(J4="Sim", L4="Alto"),"Negado","Aceito") -> Aceito | N4: =IF(AND(I4> 50000, J4 = "Sim"),"Negativa", "Positiva") -> Positiva | O4: 51500 | P4: =IF(AND(Q4=1,A4="Ativo"), O4*1.08, 0) -> 55620 | Q4: =IF(AND(M4="Negado", N4="Negativa"),0,1) -> 1
A5: Ativo | B5: Jorah Dondarrion | C5: 000.000.210-00 | D5: 63 | E5: 23156 | F5: Pyke | G5: Ilhas De Ferro | H5: 10400 | I5: 8500 | J5: Não | K5: 39 | L5: =IFS(K5<=10,"Baixo",K5<=25, "Médio", K5>25, "Alto") -> Alto | M5: =IF(AND(J5="Sim", L5="Alto"),"Negado","Aceito") -> Aceito | N5: =IF(AND(I5> 50000, J5 = "Sim"),"Negativa", "Positiva") -> Positiva | O5: 36500 | P5: =IF(AND(Q5=1,A5="Ativo"), O5*1.08, 0) -> 39420 | Q5: =IF(AND(M5="Negado", N5="Negativa"),0,1) -> 1
A6: Ativo | B6: Jojen Florent | C6: 000.000.321-00 | D6: 33 | E6: 34299 | F6: Ninho da Águia | G6: Vale | H6: 30000 | I6: - | J6: Não | K6: 5 | L6: =IFS(K6<=10,"Baixo",K6<=25, "Médio", K6>25, "Alto") -> Baixo | M6: =IF(AND(J6="Sim", L6="Alto"),"Negado","Aceito") -> Aceito | N6: =IF(AND(I6> 50000, J6 = "Sim"),"Negativa", "Positiva") -> Positiva | O6: 65000 | P6: =IF(AND(Q6=1,A6="Ativo"), O6*1.08, 0) -> 70200 | Q6: =IF(AND(M6="Negado", N6="Negativa"),0,1) -> 1
A7: Ativo | B7: Olenna Baelish | C7: 000.000.191-00 | D7: 48 | E7: 28647 | F7: Lannisporto | G7: Oeste | H7: 13200 | I7: 3500 | J7: Não | K7: 1 | L7: =IFS(K7<=10,"Baixo",K7<=25, "Médio", K7>25, "Alto") -> Baixo | M7: =IF(AND(J7="Sim", L7="Alto"),"Negado","Aceito") -> Aceito | N7: =IF(AND(I7> 50000, J7 = "Sim"),"Negativa", "Positiva") -> Positiva | O7: 32500 | P7: =IF(AND(Q7=1,A7="Ativo"), O7*1.08, 0) -> 35100 | Q7: =IF(AND(M7="Negado", N7="Negativa"),0,1) -> 1
A8: Ativo | B8: Brienne Manderly | C8: 000.000.076-00 | D8: 28 | E8: 35887 | F8: Lannisporto | G8: Oeste | H8: 8600 | I8: 19000 | J8: Sim | K8: 4 | L8: =IFS(K8<=10,"Baixo",K8<=25, "Médio", K8>25, "Alto") -> Baixo | M8: =IF(AND(J8="Sim", L8="Alto"),"Negado","Aceito") -> Aceito | N8: =IF(AND(I8> 50000, J8 = "Sim"),"Negativa", "Positiva") -> Positiva | O8: 32500 | P8: =IF(AND(Q8=1,A8="Ativo"), O8*1.08, 0) -> 35100 | Q8: =IF(AND(M8="Negado", N8="Negativa"),0,1) -> 1
A9: Inativo | B9: Yara Targaryen | C9: 000.000.059-00 | D9: 42 | E9: 30899 | F9: Pyke | G9: Ilhas De Ferro | H9: 18200 | I9: 31000 | J9: Não | K9: 19 | L9: =IFS(K9<=10,"Baixo",K9<=25, "Médio", K9>25, "Alto") -> Médio | M9: =IF(AND(J9="Sim", L9="Alto"),"Negado","Aceito") -> Aceito | N9: =IF(AND(I9> 50000, J9 = "Sim"),"Negativa", "Positiva") -> Positiva | O9: 63500 | P9: =IF(AND(Q9=1,A9="Ativo"), O9*1.08, 0) -> 0 | Q9: =IF(AND(M9="Negado", N9="Negativa"),0,1) -> 1
A10: Ativo | B10: Margaery Tarly | C10: 000.000.274-00 | D10: 34 | E10: 33624 | F10: Pyke | G10: Ilhas De Ferro | H10: 8000 | I10: 14.5 | J10: Sim | K10: 9 | L10: =IFS(K10<=10,"Baixo",K10<=25, "Médio", K10>25, "Alto") -> Baixo | M10: =IF(AND(J10="Sim", L10="Alto"),"Negado","Aceito") -> Aceito | N10: =IF(AND(I10> 50000, J10 = "Sim"),"Negativa", "Positiva") -> Positiva | O10: 17500 | P10: =IF(AND(Q10=1,A10="Ativo"), O10*1.08, 0) -> 18900 | Q10: =IF(AND(M10="Negado", N10="Negativa"),0,1) -> 1
A11: Inativo | B11: Viserys Seaworth | C11: 000.000.024-00 | D11: 62 | E11: 23667 | F11: Meereen | G11: Essos | H11: 23000 | I11: 44500 | J11: Sim | K11: 32 | L11: =IFS(K11<=10,"Baixo",K11<=25, "Médio", K11>25, "Alto") -> Alto | M11: =IF(AND(J11="Sim", L11="Alto"),"Negado","Aceito") -> Negado | N11: =IF(AND(I11> 50000, J11 = "Sim"),"Negativa", "Positiva") -> Positiva | O11: 2000 | P11: =IF(AND(Q11=1,A11="Ativo"), O11*1.08, 0) -> 0 | Q11: =IF(AND(M11="Negado", N11="Negativa"),0,1) -> 1
A12: Ativo | B12: Tormund Cerwyn | C12: 000.000.039-00 | D12: 33 | E12: 34147 | F12: Meereen | G12: Essos | H12: 28700 | I12: 12500 | J12: Não | K12: 41 | L12: =IFS(K12<=10,"Baixo",K12<=25, "Médio", K12>25, "Alto") -> Alto | M12: =IF(AND(J12="Sim", L12="Alto"),"Negado","Aceito") -> Aceito | N12: =IF(AND(I12> 50000, J12 = "Sim"),"Negativa", "Positiva") -> Positiva | O12: 99500 | P12: =IF(AND(Q12=1,A12="Ativo"), O12*1.08, 0) -> 107460 | Q12: =IF(AND(M12="Negado", N12="Negativa"),0,1) -> 1
A13: Ativo | B13: Catelyn Westerling | C13: 35800 | D13: 70 | E13: 20515 | F13: Braavos | G13: Essos | H13: 19500 | I13: 62000 | J13: Sim | K13: 45 | L13: =IFS(K13<=10,"Baixo",K13<=25, "Médio", K13>25, "Alto") -> Alto | M13: =IF(AND(J13="Sim", L13="Alto"),"Negado","Aceito") -> Negado | N13: =IF(AND(I13> 50000, J13 = "Sim"),"Negativa", "Positiva") -> Negativa | O13: 35500 | P13: =IF(AND(Q13=1,A13="Ativo"), O13*1.08, 0) -> 0 | Q13: =IF(AND(M13="Negado", N13="Negativa"),0,1) -> 0
A14: Ativo | B14: Robb Baratheon | C14: 000.000.365-00 | D14: 54 | E14: 26382 | F14: Ponta Tempestade | G14: Terras Da Tempestade | H14: 22100 | I14: 37000 | J14: Não | K14: 34 | L14: =IFS(K14<=10,"Baixo",K14<=25, "Médio", K14>25, "Alto") -> Alto | M14: =IF(AND(J14="Sim", L14="Alto"),"Negado","Aceito") -> Aceito | N14: =IF(AND(I14> 50000, J14 = "Sim"),"Negativa", "Positiva") -> Positiva | O14: 87000 | P14: =IF(AND(Q14=1,A14="Ativo"), O14*1.08, 0) -> 93960 | Q14: =IF(AND(M14="Negado", N14="Negativa"),0,1) -> 1
A15: Ativo | B15: Asha Tallhart | C15: 8600 | D15: 38 | E15: 32260 | F15: Pyke | G15: Ilhas De Ferro | H15: 17600 | I15: 0 | J15: Sim | K15: 31 | L15: =IFS(K15<=10,"Baixo",K15<=25, "Médio", K15>25, "Alto") -> Alto | M15: =IF(AND(J15="Sim", L15="Alto"),"Negado","Aceito") -> Negado | N15: =IF(AND(I15> 50000, J15 = "Sim"),"Negativa", "Positiva") -> Positiva | O15: 47500 | P15: =IF(AND(Q15=1,A15="Ativo"), O15*1.08, 0) -> 51300 | Q15: =IF(AND(M15="Negado", N15="Negativa"),0,1) -> 1
A16: Inativo | B16: Missandei Tarly | C16: 200 | D16: 56 | E16: 25892 | F16: Ponta Tempestade | G16: Terras Da Tempestade | H16: 5300 | I16: 6.5 | J16: Não | K16: 42 | L16: =IFS(K16<=10,"Baixo",K16<=25, "Médio", K16>25, "Alto") -> Alto | M16: =IF(AND(J16="Sim", L16="Alto"),"Negado","Aceito") -> Aceito | N16: =IF(AND(I16> 50000, J16 = "Sim"),"Negativa", "Positiva") -> Positiva | O16: 96000 | P16: =IF(AND(Q16=1,A16="Ativo"), O16*1.08, 0) -> 0 | Q16: =IF(AND(M16="Negado", N16="Negativa"),0,1) -> 1
A17: Inativo | B17: Jeor Mallister | C17: 000.000.162-00 | D17: 47 | E17: 29064 | F17: Correrrio | G17: Terras Fluviais | H17: 13300 | I17: 1000 | J17: Sim | K17: 24 | L17: =IFS(K17<=10,"Baixo",K17<=25, "Médio", K17>25, "Alto") -> Médio | M17: =IF(AND(J17="Sim", L17="Alto"),"Negado","Aceito") -> Aceito | N17: =IF(AND(I17> 50000, J17 = "Sim"),"Negativa", "Positiva") -> Positiva | O17: 61500 | P17: =IF(AND(Q17=1,A17="Ativo"), O17*1.08, 0) -> 0 | Q17: =IF(AND(M17="Negado", N17="Negativa"),0,1) -> 1
A18: Inativo | B18: Eddard Crakehall | C18: 31800 | D18: 43 | E18: 30391 | F18: Castelo Negro | G18: Norte | H18: 7100 | I18: 5500 | J18: Não | K18: 23 | L18: =IFS(K18<=10,"Baixo",K18<=25, "Médio", K18>25, "Alto") -> Médio | M18: =IF(AND(J18="Sim", L18="Alto"),"Negado","Aceito") -> Aceito | N18: =IF(AND(I18> 50000, J18 = "Sim"),"Negativa", "Positiva") -> Positiva | O18: 67000 | P18: =IF(AND(Q18=1,A18="Ativo"), O18*1.08, 0) -> 0 | Q18: =IF(AND(M18="Negado", N18="Negativa"),0,1) -> 1
A19: Ativo | B19: Podrick Swyft | C19: 000.000.090-00 | D19: 32 | E19: 34398 | F19: Correrrio | G19: Terras Fluviais | H19: 21300 | I19: 48000 | J19: Não | K19: 11 | L19: =IFS(K19<=10,"Baixo",K19<=25, "Médio", K19>25, "Alto") -> Médio | M19: =IF(AND(J19="Sim", L19="Alto"),"Negado","Aceito") -> Aceito | N19: =IF(AND(I19> 50000, J19 = "Sim"),"Negativa", "Positiva") -> Positiva | O19: 35000 | P19: =IF(AND(Q19=1,A19="Ativo"), O19*1.08, 0) -> 37800 | Q19: =IF(AND(M19="Negado", N19="Negativa"),0,1) -> 1
A20: Ativo | B20: Podrick Dayne | C20: 22300 | D20: 26 | E20: 36536 | F20: Vilavelha | G20: Campina | H20: 9400 | I20: 51500 | J20: Não | K20: 14 | L20: =IFS(K20<=10,"Baixo",K20<=25, "Médio", K20>25, "Alto") -> Médio | M20: =IF(AND(J20="Sim", L20="Alto"),"Negado","Aceito") -> Aceito | N20: =IF(AND(I20> 50000, J20 = "Sim"),"Negativa", "Positiva") -> Positiva | O20: 29500 | P20: =IF(AND(Q20=1,A20="Ativo"), O20*1.08, 0) -> 31860 | Q20: =IF(AND(M20="Negado", N20="Negativa"),0,1) -> 1
A21: Ativo | B21: Ellaria Seaworth | C21: 000.000.125-00 | D21: 23 | E21: 37627 | F21: Correrrio | G21: Terras Fluviais | H21: 0 | I21: 69000 | J21: Não | K21: 20 | L21: =IFS(K21<=10,"Baixo",K21<=25, "Médio", K21>25, "Alto") -> Médio | M21: =IF(AND(J21="Sim", L21="Alto"),"Negado","Aceito") -> Aceito | N21: =IF(AND(I21> 50000, J21 = "Sim"),"Negativa", "Positiva") -> Positiva | O21: 69000 | P21: =IF(AND(Q21=1,A21="Ativo"), O21*1.08, 0) -> 74520 | Q21: =IF(AND(M21="Negado", N21="Negativa"),0,1) -> 1
A22: Inativo | B22: Melisandre Clegane | C22: 000.000.231-00 | D22: 54 | E22: 26629 | F22: Ilha dos Ursos | G22: Norte | H22: 16500 | I22: 4000 | J22: Não | K22: 14 | L22: =IFS(K22<=10,"Baixo",K22<=25, "Médio", K22>25, "Alto") -> Médio | M22: =IF(AND(J22="Sim", L22="Alto"),"Negado","Aceito") -> Aceito | N22: =IF(AND(I22> 50000, J22 = "Sim"),"Negativa", "Positiva") -> Positiva | O22: 36000 | P22: =IF(AND(Q22=1,A22="Ativo"), O22*1.08, 0) -> 0 | Q22: =IF(AND(M22="Negado", N22="Negativa"),0,1) -> 1
A23: Ativo | B23: Robert Karstark | C23: 000.000.184-00 | D23: 68 | E23: 21378 | F23: Meereen | G23: Essos | H23: 14300 | I23: 32500 | J23: Sim | K23: 15 | L23: =IFS(K23<=10,"Baixo",K23<=25, "Médio", K23>25, "Alto") -> Médio | M23: =IF(AND(J23="Sim", L23="Alto"),"Negado","Aceito") -> Aceito | N23: =IF(AND(I23> 50000, J23 = "Sim"),"Negativa", "Positiva") -> Positiva | O23: 8000 | P23: =IF(AND(Q23=1,A23="Ativo"), O23*1.08, 0) -> 8640 | Q23: =IF(AND(M23="Negado", N23="Negativa"),0,1) -> 1
A24: Inativo | B24: Rhaegar Stark | C24: 000.000.119-00 | D24: 33 | E24: 34082 | F24: Meereen | G24: Essos | H24: 23600 | I24: 75.5 | J24: Não | K24: 16 | L24: =IFS(K24<=10,"Baixo",K24<=25, "Médio", K24>25, "Alto") -> Médio | M24: =IF(AND(J24="Sim", L24="Alto"),"Negado","Aceito") -> Aceito | N24: =IF(AND(I24> 50000, J24 = "Sim"),"Negativa", "Positiva") -> Positiva | O24: 88000 | P24: =IF(AND(Q24=1,A24="Ativo"), O24*1.08, 0) -> 0 | Q24: =IF(AND(M24="Negado", N24="Negativa"),0,1) -> 1
A25: Ativo | B25: Loras Greyjoy | C25: 000.000.362-00 | D25: 69 | E25: 21145 | F25: Fosso Cailin | G25: Norte | H25: 29000 | I25: 67500 | J25: Não | K25: 25 | L25: =IFS(K25<=10,"Baixo",K25<=25, "Médio", K25>25, "Alto") -> Médio | M25: =IF(AND(J25="Sim", L25="Alto"),"Negado","Aceito") -> Aceito | N25: =IF(AND(I25> 50000, J25 = "Sim"),"Negativa", "Positiva") -> Positiva | O25: 18000 | P25: =IF(AND(Q25=1,A25="Ativo"), O25*1.08, 0) -> 19440 | Q25: =IF(AND(M25="Negado", N25="Negativa"),0,1) -> 1
A26: Inativo | B26: Jorah Hightower | C26: 000.000.346-00 | D26: 63 | E26: 23140 | F26: Pedra do Dragão | G26: Terras Da Coroa | H26: 0 | I26: 0 | J26: Sim | K26: 1 | L26: =IFS(K26<=10,"Baixo",K26<=25, "Médio", K26>25, "Alto") -> Baixo | M26: =IF(AND(J26="Sim", L26="Alto"),"Negado","Aceito") -> Aceito | N26: =IF(AND(I26> 50000, J26 = "Sim"),"Negativa", "Positiva") -> Positiva | O26: 12000 | P26: =IF(AND(Q26=1,A26="Ativo"), O26*1.08, 0) -> 0 | Q26: =IF(AND(M26="Negado", N26="Negativa"),0,1) -> 1
A27: Ativo | B27: Loras Clegane | C27: 000.000.287-00 | D27: 58 | E27: 24911 | F27: Harrenhal | G27: Terras Fluviais | H27: 25400 | I27: 70500 | J27: Sim | K27: 11 | L27: =IFS(K27<=10,"Baixo",K27<=25, "Médio", K27>25, "Alto") -> Médio | M27: =IF(AND(J27="Sim", L27="Alto"),"Negado","Aceito") -> Aceito | N27: =IF(AND(I27> 50000, J27 = "Sim"),"Negativa", "Positiva") -> Negativa | O27: 47000 | P27: =IF(AND(Q27=1,A27="Ativo"), O27*1.08, 0) -> 50760 | Q27: =IF(AND(M27="Negado", N27="Negativa"),0,1) -> 1
A28: Ativo | B28: Jojen Florent | C28: 34300 | D28: 49 | E28: 28408 | F28: Winterfell | G28: Norte | H28: 13300 | I28: 42000 | J28: Sim | K28: 27 | L28: =IFS(K28<=10,"Baixo",K28<=25, "Médio", K28>25, "Alto") -> Alto | M28: =IF(AND(J28="Sim", L28="Alto"),"Negado","Aceito") -> Negado | N28: =IF(AND(I28> 50000, J28 = "Sim"),"Negativa", "Positiva") -> Positiva | O28: 40000 | P28: =IF(AND(Q28=1,A28="Ativo"), O28*1.08, 0) -> 43200 | Q28: =IF(AND(M28="Negado", N28="Negativa"),0,1) -> 1
A29: Ativo | B29: Samwell Yronwood | C29: 000.000.124-00 | D29: 30 | E29: 35323 | F29: Jardim de Cima | G29: Campina | H29: 21200 | I29: 75000 | J29: Não | K29: 6 | L29: =IFS(K29<=10,"Baixo",K29<=25, "Médio", K29>25, "Alto") -> Baixo | M29: =IF(AND(J29="Sim", L29="Alto"),"Negado","Aceito") -> Aceito | N29: =IF(AND(I29> 50000, J29 = "Sim"),"Negativa", "Positiva") -> Positiva | O29: 63500 | P29: =IF(AND(Q29=1,A29="Ativo"), O29*1.08, 0) -> 68580 | Q29: =IF(AND(M29="Negado", N29="Negativa"),0,1) -> 1
A30: Ativo | B30: Catelyn Yronwood | C30: 000.000.226-00 | D30: 38 | E30: 32166 | F30: Castelo Negro | G30: Norte | H30: 19500 | I30: 39000 | J30: Não | K30: 25 | L30: =IFS(K30<=10,"Baixo",K30<=25, "Médio", K30>25, "Alto") -> Médio | M30: =IF(AND(J30="Sim", L30="Alto"),"Negado","Aceito") -> Aceito | N30: =IF(AND(I30> 50000, J30 = "Sim"),"Negativa", "Positiva") -> Positiva | O30: 88500 | P30: =IF(AND(Q30=1,A30="Ativo"), O30*1.08, 0) -> 95580 | Q30: =IF(AND(M30="Negado", N30="Negativa"),0,1) -> 1
A31: Inativo | B31: Brienne Reed | C31: 000.000.306-00 | D31: 68 | E31: 21293 | F31: Pyke | G31: Ilhas De Ferro | H31: 3800 | I31: 70000 | J31: Sim | K31: 34 | L31: =IFS(K31<=10,"Baixo",K31<=25, "Médio", K31>25, "Alto") -> Alto | M31: =IF(AND(J31="Sim", L31="Alto"),"Negado","Aceito") -> Negado | N31: =IF(AND(I31> 50000, J31 = "Sim"),"Negativa", "Positiva") -> Negativa | O31: 7500 | P31: =IF(AND(Q31=1,A31="Ativo"), O31*1.08, 0) -> 0 | Q31: =IF(AND(M31="Negado", N31="Negativa"),0,1) -> 0
A32: Ativo | B32: Rhaegar Umber | C32: 000.000.247-00 | D32: 19 | E32: 39220 | F32: Vilavelha | G32: Campina | H32: 18000 | I32: 50500 | J32: Sim | K32: 11 | L32: =IFS(K32<=10,"Baixo",K32<=25, "Médio", K32>25, "Alto") -> Médio | M32: =IF(AND(J32="Sim", L32="Alto"),"Negado","Aceito") -> Aceito | N32: =IF(AND(I32> 50000, J32 = "Sim"),"Negativa", "Positiva") -> Negativa | O32: 26000 | P32: =IF(AND(Q32=1,A32="Ativo"), O32*1.08, 0) -> 28080 | Q32: =IF(AND(M32="Negado", N32="Negativa"),0,1) -> 1
A33: Ativo | B33: Roose Manderly | C33: 15400 | D33: 43 | E33: 30642 | F33: Dorne | G33: Dorne | H33: 0 | I33: 19500 | J33: Não | K33: 42 | L33: =IFS(K33<=10,"Baixo",K33<=25, "Médio", K33>25, "Alto") -> Alto | M33: =IF(AND(J33="Sim", L33="Alto"),"Negado","Aceito") -> Aceito | N33: =IF(AND(I33> 50000, J33 = "Sim"),"Negativa", "Positiva") -> Positiva | O33: 89500 | P33: =IF(AND(Q33=1,A33="Ativo"), O33*1.08, 0) -> 96660 | Q33: =IF(AND(M33="Negado", N33="Negativa"),0,1) -> 1
A34: Ativo | B34: Jeor Florent | C34: 000.000.249-00 | D34: 27 | E34: 36319 | F34: Ponta Tempestade | G34: Terras Da Tempestade | H34: 28800 | I34: 78.5 | J34: Não | K34: 2 | L34: =IFS(K34<=10,"Baixo",K34<=25, "Médio", K34>25, "Alto") -> Baixo | M34: =IF(AND(J34="Sim", L34="Alto"),"Negado","Aceito") -> Aceito | N34: =IF(AND(I34> 50000, J34 = "Sim"),"Negativa", "Positiva") -> Positiva | O34: 53000 | P34: =IF(AND(Q34=1,A34="Ativo"), O34*1.08, 0) -> 57240 | Q34: =IF(AND(M34="Negado", N34="Negativa"),0,1) -> 1
A35: Ativo | B35: Bran Yronwood | C35: 000.000.057-00 | D35: 42 | E35: 30878 | F35: Pyke | G35: Ilhas De Ferro | H35: 17500 | I35: 3500 | J35: Não | K35: 25 | L35: =IFS(K35<=10,"Baixo",K35<=25, "Médio", K35>25, "Alto") -> Médio | M35: =IF(AND(J35="Sim", L35="Alto"),"Negado","Aceito") -> Aceito | N35: =IF(AND(I35> 50000, J35 = "Sim"),"Negativa", "Positiva") -> Positiva | O35: 35000 | P35: =IF(AND(Q35=1,A35="Ativo"), O35*1.08, 0) -> 37800 | Q35: =IF(AND(M35="Negado", N35="Negativa"),0,1) -> 1
A36: Ativo | B36: Bronn Arryn | C36: 000.000.016-00 | D36: 44 | E36: 29975 | F36: Lannisporto | G36: Oeste | H36: 5300 | I36: 6000 | J36: Sim | K36: 1 | L36: =IFS(K36<=10,"Baixo",K36<=25, "Médio", K36>25, "Alto") -> Baixo | M36: =IF(AND(J36="Sim", L36="Alto"),"Negado","Aceito") -> Aceito | N36: =IF(AND(I36> 50000, J36 = "Sim"),"Negativa", "Positiva") -> Positiva | O36: 4500 | P36: =IF(AND(Q36=1,A36="Ativo"), O36*1.08, 0) -> 4860 | Q36: =IF(AND(M36="Negado", N36="Negativa"),0,1) -> 1
A37: Ativo | B37: Shae Clegane | C37: 000.000.205-00 | D37: 40 | E37: 31598 | F37: Fosso Cailin | G37: Norte | H37: 9900 | I37: 3500 | J37: Não | K37: 1 | L37: =IFS(K37<=10,"Baixo",K37<=25, "Médio", K37>25, "Alto") -> Baixo | M37: =IF(AND(J37="Sim", L37="Alto"),"Negado","Aceito") -> Aceito | N37: =IF(AND(I37> 50000, J37 = "Sim"),"Negativa", "Positiva") -> Positiva | O37: 23500 | P37: =IF(AND(Q37=1,A37="Ativo"), O37*1.08, 0) -> 25380 | Q37: =IF(AND(M37="Negado", N37="Negativa"),0,1) -> 1
A38: Ativo | B38: Ramsay Hornwood | C38: 000.000.005-00 | D38: 66 | E38: 22236 | F38: Pyke | G38: Ilhas De Ferro | H38: 23400 | I38: 28000 | J38: Não | K38: 34 | L38: =IFS(K38<=10,"Baixo",K38<=25, "Médio", K38>25, "Alto") -> Alto | M38: =IF(AND(J38="Sim", L38="Alto"),"Negado","Aceito") -> Aceito | N38: =IF(AND(I38> 50000, J38 = "Sim"),"Negativa", "Positiva") -> Positiva | O38: 74000 | P38: =IF(AND(Q38=1,A38="Ativo"), O38*1.08, 0) -> 79920 | Q38: =IF(AND(M38="Negado", N38="Negativa"),0,1) -> 1
B39: Meera Payne | C39: 000.000.131-00 | D39: 64 | E39: 22974 | F39: Dorne | G39: Dorne | H39: 14700 | I39: 0 | J39: Sim | K39: 40 | L39: =IFS(K39<=10,"Baixo",K39<=25, "Médio", K39>25, "Alto") -> Alto | M39: =IF(AND(J39="Sim", L39="Alto"),"Negado","Aceito") -> Negado | N39: =IF(AND(I39> 50000, J39 = "Sim"),"Negativa", "Positiva") -> Positiva | O39: 83500 | P39: =IF(AND(Q39=1,A39="Ativo"), O39*1.08, 0) -> 0 | Q39: =IF(AND(M39="Negado", N39="Negativa"),0,1) -> 1
A40: Ativo | B40: Melisandre Baratheon | C40: 000.000.364-00 | D40: 127 | E40: 0 | F40: Meereen | G40: Essos | H40: 14400 | I40: 0 | J40: Não | K40: 27 | L40: =IFS(K40<=10,"Baixo",K40<=25, "Médio", K40>25, "Alto") -> Alto | M40: =IF(AND(J40="Sim", L40="Alto"),"Negado","Aceito") -> Aceito | N40: =IF(AND(I40> 50000, J40 = "Sim"),"Negativa", "Positiva") -> Positiva | O40: 33500 | P40: =IF(AND(Q40=1,A40="Ativo"), O40*1.08, 0) -> 36180 | Q40: =IF(AND(M40="Negado", N40="Negativa"),0,1) -> 1
...

Sheet Original_SemLimpeza
A1: status | B1: nome | C1: cpf | D1: idade | E1: data_nascimento | F1: cidade | G1: regiao | H1: renda_mensal | I1: credito_tomado | J1: flag_inadimplente | K1: qtde_batalhas | L1: nivel_risco | M1: valor_solicitado
A2: Ativo | B2: Ellaria Baelish | C2: 000.000.336-00 | D2: 32 | E2: 13/01/1994 | F2: Ninho da Águia | G2: Vale | H2: 15600 | I2: 0 | J2: Sim | K2: 34 | M2: 16000
A3: Inativo | B3: Stannis Lannister | C3: 36100 | D3: 24 | E3: 26/02/2002 | F3: Ponta Tempestade | G3: Terras da Tempestade | H3: 11000 moedas | I3: 76500 | J3: Sim | K3: 33 | M3: 26000
A4: Ativo | B4: Asha Hornwood | C4: 000.000.363-00 | D4: 33 | E4: 34144 | F4: Pedra do Dragão | G4: Terras da Coroa | H4: 21500 moedas | I4: N/A | J4: não | K4: 22 | M4: 51500
A5: Ativo | B5: Jorah Dondarrion | C5: 000.000.210-00 | D5: 63 | E5: 23156 | F5: Pyke | Ilhas de Ferro | H5: 10400 moedas | I5: 8500 | J5: não | K5: 39 | M5: 36500
A6: Ativo | B6: Jojen Florent | C6: 000.000.321-00 | D6: 32 | E6: 34299 | F6: Ninho da Águia | G6: vale | H6: R$ 30.000,00 | J6: Não | K6: 5 | M6: 65000
A7: Ativo | B7: Olenna Baelish | C7: 000.000.191-00 | D7: 48 | E7: 28647 | F7: Lannisporto | H7: 13200 | I7: 3500 moedas | J7: Não | K7: 1 | M7: 32500
A8: ATIVO | B8: Brienne Manderly | C8: 000.000.076-00 | D8: 28 | E8: 35887 | F8: Lannisporto | G8: Oeste | H8: 8600 moedas | I8: R$ 19.000,00 | J8: Sim | K8: 4 | M8: 32500
A9: Inativo | B9: yara targaryen | C9: 000.000.059-00 | D9: 42 | E9: 30899 | F9: Pyke | G9: Ilhas De Ferro | H9: 18200 moedas | I9: 31000 moedas | J9: Não | K9: 19 | M9: 63500
A10: Ativo | B10: Margaery Tarly | C10: 000.000.274-00 | D10: 34 | E10: 21/01/1992 | F10: Pyke | G10: ilhas de ferro | H10: 8000 | I10: 14.5 | J10: Sim | K10: 9 | M10: 17500
A11: Inativo | B11: Viserys Seaworth | C11: 000.000.024-00 | D11: 61 | E11: 17/10/1964 | F11: Meereen | G11: Essos | H11: 23000 moedas | I11: 44500 | J11: Sim | K11: 32 | M11: 2000
A12: Ativo | B12: Tormund Cerwyn | C12: 000.000.039-00 | D12: 33 | E12: 34147 | F12: Meereen | G12: Essos | H12: 28700 | I12: 12500 | J12: Não | K12: 41 | M12: 99500
A13: Ativo | B13: catelyn westerling | C13: 35800 | D13: 70 | E13: 20515 | F13: Braavos | G13: Essos | H13: 19500 moedas | I13: 62000 | J13: Sim | K13: 45 | M13: 35500
A14: Ativo | B14: Robb Baratheon | C14: 000.000.365-00 | D14: 54 | E14: 24/03/1972 | F14: Ponta Tempestade | G14: Terras da Tempestade | H14: 22100 | I14: 37000 | J14: Não | K14: 34 | M14: 87000
A15: Ativo | B15: Asha Tallhart | C15: 8600 | E15: 32260 | F15: Pyke | G15: Ilhas de Ferro | H15: 17600 moedas | I15: 0 | J15: Sim | K15: 31 | M15: 47500
A16: Inativo | B16: Missandei Tarly | C16: 200 | D16: 55 | E16: 25892 | F16: Ponta Tempestade | G16: TERRAS DA TEMPESTADE | H16: 5300 | I16: 6.5 | J16: Não | K16: 42 | M16: 96000
A17: Inativo | B17: Jeor Mallister | C17: 000.000.162-00 | D17: 47 | E17: 29064 | F17: Correrrio | G17: Terras Fluviais | H17: 13300 | I17: 1000 | J17: Sim | K17: 24 | M17: 61500
A18: Inativo | B18: Eddard Crakehall | C18: 31800 | D18: 43 | E18: 30391 | F18: Castelo Negro | G18: Norte | H18: 7100 | I18: 5500 moedas | J18: Não | K18: 23 | M18: 67000
A19: Ativo | B19: Podrick Swyft | C19: 000.000.090-00 | D19: 32 | E19: 34398 | F19: Correrrio | G19: TERRAS FLUVIAIS | H19: 21.3 | I19: R$ 48.000,00 | J19: Não | K19: 11 | M19: 35000
A20: Ativo | B20: Podrick Dayne | C20: 22300 | D20: 25 | E20: 36536 | F20: Vilavelha | G20: Campina | H20: 9.4 | I20: 51500 | J20: Não | K20: 14 | M20: 29500
A21: Ativo | B21: Ellaria Seaworth | C21: 000.000.125-00 | D21: 23 | E21: 37627 | F21: Correrrio | G21: TERRAS FLUVIAIS | I21: 69000 | J21: Não | K21: 20 | M21: 69000
A22: Inativo | B22: Melisandre Clegane | C22: 000.000.231-00 | D22: 53 | E22: 26/11/1972 | F22: Ilha dos Ursos | G22: NORTE | H22: 16.5 | I22: R$ 4.000,00 | J22: Não | K22: 14 | M22: 36000
A23: Ativo | B23: Robert Karstark | C23: 000.000.184-00 | E23: 21378 | F23: Meereen | H23: 14300 | I23: 32500 | J23: Sim | K23: 15 | M23: 8000
A24: Inativo | B24: rhaegar stark | C24: 000.000.119-00 | D24: 33 | E24: 23/04/1993 | F24: Meereen | G24: Essos | H24: 23600 | I24: 75.5 | J24: Não | K24: 16 | M24: 88000
A25: Ativo | B25: Loras Greyjoy | C25: 000.000.362-00 | D25: 68 | E25: 21145 | F25: Fosso Cailin | G25: Norte | H25: 29000 | I25: 67500 | J25: Não | K25: 25 | M25: 18000
A26: Inativo | B26: Jorah Hightower | C26: 000.000.346-00 | D26: 62 | E26: 23140 | F26: Pedra do Dragão | G26: TERRAS DA COROA | I26: 0 | J26: Sim | K26: 1 batalhas | M26: 12000
A27: Ativo | B27: Loras Clegane | C27: 000.000.287-00 | D27: 58 | E27: 24911 | F27: Harrenhal | G27: Terras Fluviais | H27: R$ 25.400,00 | I27: 70500 | J27: Sim | K27: 11 | M27: 47000
A28: Ativo | B28: Jojen Florent | C28: 34300 | D28: 48 | E28: 28408 | F28: Winterfell | H28: 13.3 | I28: 42000 | J28: Sim | K28: 27 | M28: 40000
A29: Ativo | B29: samwell yronwood | C29: 000.000.124-00 | D29: 29 | E29: 35323 | F29: Jardim de Cima | G29: Campina | H29: 21200 | I29: 75000 | J29: Não | K29: 6 | M29: 63500
A30: Ativoo | B30: Catelyn Yronwood | C30: 000.000.226-00 | D30: 38 | E30: 32166 | F30: Castelo Negro | G30: norte | H30: 19500 moedas | I30: 39000 | J30: Não | K30: 25 | M30: 88500
A31: Inativo | B31: Brienne Reed | C31: 000.000.306-00 | D31: 68 | E31: 21293 | F31: Pyke | G31: Ilhas de Ferro | H31: 3800 | I31: 70000 | J31: Sim | K31: 34 | M31: 7500
A32: Ativo | B32: Rhaegar Umber | C32: 000.000.247-00 | D32: 19 | E32: 18/05/2007 | F32: Vilavelha | G32: Campina | H32: 18000 | I32: 50500 | J32: sim | K32: 11 | M32: 26000
A33: Ativo | B33: Roose Manderly | C33: 15400 | D33: 42 | E33: 30642 | F33: Dorne | G33: Dorne | H33: sem renda | I33: 19500 | J33: Não | K33: 42 | M33: 89500
A34: Ativo | B34: Jeor Florent | C34: 000.000.249-00 | D34: 27 | E34: 36319 | F34: Ponta Tempestade | G34: terras da tempestade | H34: 28800 | I34: 78.5 | J34: Não | K34: 2 | M34: 53000
A35: Ativo | B35: Bran Yronwood | C35: 000.000.057-00 | D35: 42 | E35: 30878 | F35: Pyke | G35: Ilhas de Ferro | H35: 17500 | I35: 3500 | J35: Nao | K35: 25 | M35: 35000
A36: Ativo | B36: BRONN ARRYN | C36: 000.000.016-00 | D36: 44 | E36: 29975 | F36: Lannisporto | G36: oeste | H36: 5300 | I36: 6000 | J36: Sim | K36: 1 | M36: 4500
A37: Ativo | B37: Shae Clegane | C37: 000.000.205-00 | D37: 40 | E37: 31598 | F37: Fosso Cailin | G37: Norte | H37: 9900 | I37: 3500 | J37: Não | K37: 1 | M37: 23500
A38: Ativo | B38: Ramsay Hornwood | C38: 000.000.005-00 | D38: 65 | E38: 16/11/1960 | F38: Pyke | G38: Ilhas De Ferro | H38: 23400 moedas | I38: 28000 | J38: Não | K38: 34 | M38: 74000
B39: MEERA PAYNE | C39: 000.000.131-00 | D39: 63 | E39: 22974 | F39: Dorne | G39: DORNE | H39: R$ 14.700,00 | I39: 0 | J39: sim | K39: 40 | M39: 83500
A40: Ativo | B40: MELISANDRE BARATHEON | C40: 000.000.364-00 | D40: 22 | F40: Meereen | G40: Essos | H40: 14400 | I40: 0 | J40: Não | K40: 27 batalhas | M40: 33500
...

Sheet Gráfico
B1: Qual a porcentagem negada de liberação de crédito entre os inadimplentes?
B2: inadimplentes | C2: créditos_negados | D2: percentual_negado | E2: percentual_aprovado
A3: Renda maior que 20 mil | B3: =COUNTIFS(Panilha_tratada!$J:$J, "Sim", Panilha_tratada!$H:$H, ">=20000") -> 29 | C3: =COUNTIFS(Panilha_tratada!$J:$J, "Sim", Panilha_tratada!$H:$H, ">20000",Panilha_tratada!$P:$P, 0) -> 12 | D3: =C3 / B3 -> 0.4137931 | E3: =1 - D3 -> 0.5862069
A4: Renda entre 10 e 20 mil | B4: =COUNTIFS(Panilha_tratada!$J:$J, "Sim", Panilha_tratada!$H:$H, ">=10000", Panilha_tratada!$H:$H, "<20000") -> 27 | C4: =COUNTIFS(Panilha_tratada!$J:$J, "Sim", Panilha_tratada!$H:$H, ">=10000", Panilha_tratada!$H:$H, "<20000",Panilha_tratada!$P:$P, 0) -> 11 | D4: =C4 / B4 -> 0.40740741 | E4: =1 - D4 -> 0.59259259
A5: Renda menor que 10 mil | B5: =COUNTIFS(Panilha_tratada!$J:$J, "Sim", Panilha_tratada!$H:$H, "<10000") -> 29 | C5: =COUNTIFS(Panilha_tratada!$J:$J, "Sim", Panilha_tratada!$H:$H, "<10000",Panilha_tratada!$P:$P, 0) -> 13 | D5: =C5 / B5 -> 0.44827586 | E5: =1 - D5 -> 0.55172414
A6: Total | B6: =COUNTIFS(Panilha_tratada!$J:$J, "Sim") -> 85 | C6: =COUNTIFS(Panilha_tratada!$J:$J, "Sim", Panilha_tratada!$P:$P, 0) -> 36 | D6: =C6 / B6 -> 0.42352941 | E6: =1 - D6 -> 0.57647059

Sheet Relatório
A1: Coluna analisada | B1: Problema encontrado | C1: Exemplo encontrado | D1: Tipo do problema | E1: Ação realizada | F1: Resultado esperado | G1: Decisão
A2: status | B2: Categorias escritas de formas diferentes e valores inconsistentes | C2: ATIVO, ativo, Ativoo, loqueado | D2: Padronização / Qualidade | E2: Padronização das categorias para Ativo e Inativo | F2: Uma única categoria válida para cada status | G2: Corrigido
A3: nome | B3: Nomes com diferenças de maiúsculas e minúsculas e registros sem nome | C3: yara targaryen / BRONN ARRYN / célula vazia | D3: Padronização / Qualidade | E3: Aplicado padrão de capitalização aos nomes; valores vazios foram mantidos | F3: Uma padronização nos nomes e manutenção dos valores que não podem ser recuperados | G3: Corrigido
A4: cpf | B4: Valores numéricos sem a formatação padrão de CPF | C4: 3300 / 36100 | D4: Formatação | E4: Aplicada formatação personalizada 000"."000"."000"-"00 | F4: Valores exibidos no formato 000.000.000-00 | G4: Corrigido
A5: idade | B5: Valores ausentes ou inconsistentes com a data de nascimento | C5: 32 → 33 / células vazias | D5: Qualidade | E5: Recalculada a idade a partir da data de nascimento | F5: Idade consistente com a data de nascimento | G5: Corrigido
A6: data_nascimento | B6: Datas em formatos diferentes e valores armazenados como número | C6: 13/01/1994 / 34144 | D6: Formatação / Tipo | E6: Conversão dos valores para o formato de data | F6: Valores reconhecidos como datas e apresentados no mesmo formato | G6: Corrigido
A7: cidade | B7: Existem valores vazios que não podem ser recuperados | C7: Pyke / célula vazia | D7: Qualidade | E7: Valores disponíveis foram mantidos e células vazias sem informação foram deixadas vazias | F7: Cidade preenchida quando existe informação disponível | G7: Registrado
A8: regiao | B8: Regiões com diferenças de escrita ou informações ausentes | C8: vale / célula vazia | D8: Qualidade / Padronização | E8: Padronização dos valores e preenchimento quando a informação permitia | F8: Uma região padronizada para cada registro quando possível | G8: Corrigido
A9: renda_mensal | B9: Valores misturados entre números, moedas e textos | C9: R$ 8.900,00 / 11000 moedas | D9: Qualidade / Tipo | E9: Removidos textos e símbolos desnecessários e valores convertidos para número | F9: Valores numéricos consistentes na coluna | G9: Corrigido
A10: credito_tomado | B10: Mistura de números, valores monetários e células com N/A | C10: 3500 moedas / R$ 19.000,00 / N/A | D10: Qualidade / Negócio | E10: Valores monetários convertidos para número e diferenças de ausência preservadas | F10: Valores numéricos sem perder o significado de ausência | G10: Registrado
A11: flag_inadimplente | B11: Categorias equivalentes escritas de formas diferentes | C11: SIM, sim, NÃO, não, Nao, 0, 1 | D11: Padronização | E11: Conversão dos valores para as categorias Sim e Não | F11: Somente categorias padronizadas Sim ou Não | G11: Corrigido
A12: qtde_batalhas | B12: Texto junto ao valor numérico | C12: 44 batalhas | D12: Qualidade / Tipo | E12: Removido o texto e convertido o valor para número | F12: Quantidade numérica pronta para análise | G12: Corrigido
... A14: valor_solicitado | B14: Valor apresentado incorretamente na base tratada | C14: 43.500 → 63.500 | D14: Qualidade / Auditoria | E14: Valor corrigido de acordo com a verificação realizada | F14: Valor solicitado correto e consistente com a base | G14: Corrigido

Sheet Fórmulas
A1: Formulas(nao todas)
A2: /=PROPER()
A3: /=2026-YEAR(F2)
A4: /=IF(I2 = "";"N/A"; I2)
A5: /=VALUE(H2)
A6: /=IFS(J2 = "";"N/A";J2 = "0";"Não"; J2= "1"; "Sim"; J2="Sim"; J2; J2="Não"; J2)
A7: /=IFS(AND(M2="Negado"; N2="Negativa"); "0"; AND(M2="Aceito"; N2="Positiva"; A2="Inativo"); "00";AND(M2="Aceito"; N2="Positiva"; A2="Ativo"); "1";)
A8: /=IF(H2<100; H2*1000; H2)
